<?xml version="1.0" encoding="UTF-8"?>
<testng-results skipped="1" failed="3" total="6" passed="2">
  <reporter-output>
  </reporter-output>
  <suite name="MainSuite" duration-ms="173804" started-at="2017-05-03T12:46:44Z" finished-at="2017-05-03T12:49:37Z">
    <groups>
    </groups>
    <test name="testsuite-1" duration-ms="133265" started-at="2017-05-03T12:46:44Z" finished-at="2017-05-03T12:48:57Z">
      <class name="com.chefd.SanityCases">
        <test-method status="PASS" signature="launch_chefd()[pri:0, instance:com.chefd.SanityCases@4a07d605]" name="launch_chefd" is-config="true" duration-ms="15773" started-at="2017-05-03T18:16:44Z" finished-at="2017-05-03T18:16:59Z">
          <reporter-output>
          </reporter-output>
        </test-method> <!-- launch_chefd -->
        <test-method status="PASS" signature="how_it_works()[pri:0, instance:com.chefd.SanityCases@4a07d605]" name="how_it_works" duration-ms="28324" started-at="2017-05-03T18:16:59Z" finished-at="2017-05-03T18:17:28Z">
          <reporter-output>
          </reporter-output>
        </test-method> <!-- how_it_works -->
        <test-method status="PASS" signature="email_Gifts_Card()[pri:1, instance:com.chefd.SanityCases@4a07d605]" name="email_Gifts_Card" duration-ms="16643" started-at="2017-05-03T18:17:28Z" finished-at="2017-05-03T18:17:44Z">
          <reporter-output>
          </reporter-output>
        </test-method> <!-- email_Gifts_Card -->
        <test-method status="FAIL" signature="add_Receipe_To_cart_from_AllMeals()[pri:2, instance:com.chefd.SanityCases@4a07d605]" name="add_Receipe_To_cart_from_AllMeals" duration-ms="47397" started-at="2017-05-03T18:17:44Z" finished-at="2017-05-03T18:18:32Z">
          <exception class="java.lang.AssertionError">
            <message>
              <![CDATA[Adding Physical Gift Card to the cart Failed expected [true] but found [false]]]>
            </message>
            <full-stacktrace>
              <![CDATA[java.lang.AssertionError: Adding Physical Gift Card to the cart Failed expected [true] but found [false]
	at org.testng.Assert.fail(Assert.java:94)
	at org.testng.Assert.failNotEquals(Assert.java:496)
	at org.testng.Assert.assertTrue(Assert.java:42)
	at com.chefd.SanityCases.add_Receipe_To_cart_from_AllMeals(SanityCases.java:41)
	at sun.reflect.NativeMethodAccessorImpl.invoke0(Native Method)
	at sun.reflect.NativeMethodAccessorImpl.invoke(NativeMethodAccessorImpl.java:62)
	at sun.reflect.DelegatingMethodAccessorImpl.invoke(DelegatingMethodAccessorImpl.java:43)
	at java.lang.reflect.Method.invoke(Method.java:498)
	at org.testng.internal.MethodInvocationHelper.invokeMethod(MethodInvocationHelper.java:85)
	at org.testng.internal.Invoker.invokeMethod(Invoker.java:639)
	at org.testng.internal.Invoker.invokeTestMethod(Invoker.java:816)
	at org.testng.internal.Invoker.invokeTestMethods(Invoker.java:1124)
	at org.testng.internal.TestMethodWorker.invokeTestMethods(TestMethodWorker.java:125)
	at org.testng.internal.TestMethodWorker.run(TestMethodWorker.java:108)
	at org.testng.TestRunner.privateRun(TestRunner.java:774)
	at org.testng.TestRunner.run(TestRunner.java:624)
	at org.testng.SuiteRunner.runTest(SuiteRunner.java:359)
	at org.testng.SuiteRunner.runSequentially(SuiteRunner.java:354)
	at org.testng.SuiteRunner.privateRun(SuiteRunner.java:312)
	at org.testng.SuiteRunner.run(SuiteRunner.java:261)
	at org.testng.SuiteRunnerWorker.runSuite(SuiteRunnerWorker.java:52)
	at org.testng.SuiteRunnerWorker.run(SuiteRunnerWorker.java:86)
	at org.testng.TestNG.runSuitesSequentially(TestNG.java:1215)
	at org.testng.TestNG.runSuitesLocally(TestNG.java:1140)
	at org.testng.TestNG.run(TestNG.java:1048)
	at org.testng.remote.AbstractRemoteTestNG.run(AbstractRemoteTestNG.java:132)
	at org.testng.remote.RemoteTestNG.initAndRun(RemoteTestNG.java:230)
	at org.testng.remote.RemoteTestNG.main(RemoteTestNG.java:76)
]]>
            </full-stacktrace>
          </exception> <!-- java.lang.AssertionError -->
          <reporter-output>
          </reporter-output>
        </test-method> <!-- add_Receipe_To_cart_from_AllMeals -->
        <test-method status="FAIL" signature="log_in()[pri:2, instance:com.chefd.SanityCases@4a07d605]" name="log_in" duration-ms="25102" started-at="2017-05-03T18:18:32Z" finished-at="2017-05-03T18:18:57Z">
          <exception class="java.lang.AssertionError">
            <message>
              <![CDATA[Adding Physical Gift Card to the cart Failed expected [true] but found [false]]]>
            </message>
            <full-stacktrace>
              <![CDATA[java.lang.AssertionError: Adding Physical Gift Card to the cart Failed expected [true] but found [false]
	at org.testng.Assert.fail(Assert.java:94)
	at org.testng.Assert.failNotEquals(Assert.java:496)
	at org.testng.Assert.assertTrue(Assert.java:42)
	at com.chefd.SanityCases.log_in(SanityCases.java:48)
	at sun.reflect.NativeMethodAccessorImpl.invoke0(Native Method)
	at sun.reflect.NativeMethodAccessorImpl.invoke(NativeMethodAccessorImpl.java:62)
	at sun.reflect.DelegatingMethodAccessorImpl.invoke(DelegatingMethodAccessorImpl.java:43)
	at java.lang.reflect.Method.invoke(Method.java:498)
	at org.testng.internal.MethodInvocationHelper.invokeMethod(MethodInvocationHelper.java:85)
	at org.testng.internal.Invoker.invokeMethod(Invoker.java:639)
	at org.testng.internal.Invoker.invokeTestMethod(Invoker.java:816)
	at org.testng.internal.Invoker.invokeTestMethods(Invoker.java:1124)
	at org.testng.internal.TestMethodWorker.invokeTestMethods(TestMethodWorker.java:125)
	at org.testng.internal.TestMethodWorker.run(TestMethodWorker.java:108)
	at org.testng.TestRunner.privateRun(TestRunner.java:774)
	at org.testng.TestRunner.run(TestRunner.java:624)
	at org.testng.SuiteRunner.runTest(SuiteRunner.java:359)
	at org.testng.SuiteRunner.runSequentially(SuiteRunner.java:354)
	at org.testng.SuiteRunner.privateRun(SuiteRunner.java:312)
	at org.testng.SuiteRunner.run(SuiteRunner.java:261)
	at org.testng.SuiteRunnerWorker.runSuite(SuiteRunnerWorker.java:52)
	at org.testng.SuiteRunnerWorker.run(SuiteRunnerWorker.java:86)
	at org.testng.TestNG.runSuitesSequentially(TestNG.java:1215)
	at org.testng.TestNG.runSuitesLocally(TestNG.java:1140)
	at org.testng.TestNG.run(TestNG.java:1048)
	at org.testng.remote.AbstractRemoteTestNG.run(AbstractRemoteTestNG.java:132)
	at org.testng.remote.RemoteTestNG.initAndRun(RemoteTestNG.java:230)
	at org.testng.remote.RemoteTestNG.main(RemoteTestNG.java:76)
]]>
            </full-stacktrace>
          </exception> <!-- java.lang.AssertionError -->
          <reporter-output>
          </reporter-output>
        </test-method> <!-- log_in -->
        <test-method status="SKIP" signature="regular_Checkout()[pri:3, instance:com.chefd.SanityCases@4a07d605]" name="regular_Checkout" duration-ms="0" started-at="2017-05-03T18:18:57Z" depends-on-methods="com.chefd.SanityCases.add_Receipe_To_cart_from_AllMeals" finished-at="2017-05-03T18:18:57Z">
          <exception class="java.lang.Throwable">
            <message>
              <![CDATA[Method SanityCases.regular_Checkout()[pri:3, instance:com.chefd.SanityCases@4a07d605] depends on not successfully finished methods]]>
            </message>
            <full-stacktrace>
              <![CDATA[java.lang.Throwable: Method SanityCases.regular_Checkout()[pri:3, instance:com.chefd.SanityCases@4a07d605] depends on not successfully finished methods
	at org.testng.internal.Invoker.invokeTestMethods(Invoker.java:1033)
	at org.testng.internal.TestMethodWorker.invokeTestMethods(TestMethodWorker.java:125)
	at org.testng.internal.TestMethodWorker.run(TestMethodWorker.java:108)
	at org.testng.TestRunner.privateRun(TestRunner.java:774)
	at org.testng.TestRunner.run(TestRunner.java:624)
	at org.testng.SuiteRunner.runTest(SuiteRunner.java:359)
	at org.testng.SuiteRunner.runSequentially(SuiteRunner.java:354)
	at org.testng.SuiteRunner.privateRun(SuiteRunner.java:312)
	at org.testng.SuiteRunner.run(SuiteRunner.java:261)
	at org.testng.SuiteRunnerWorker.runSuite(SuiteRunnerWorker.java:52)
	at org.testng.SuiteRunnerWorker.run(SuiteRunnerWorker.java:86)
	at org.testng.TestNG.runSuitesSequentially(TestNG.java:1215)
	at org.testng.TestNG.runSuitesLocally(TestNG.java:1140)
	at org.testng.TestNG.run(TestNG.java:1048)
	at org.testng.remote.AbstractRemoteTestNG.run(AbstractRemoteTestNG.java:132)
	at org.testng.remote.RemoteTestNG.initAndRun(RemoteTestNG.java:230)
	at org.testng.remote.RemoteTestNG.main(RemoteTestNG.java:76)
]]>
            </full-stacktrace>
          </exception> <!-- java.lang.Throwable -->
          <reporter-output>
          </reporter-output>
        </test-method> <!-- regular_Checkout -->
      </class> <!-- com.chefd.SanityCases -->
    </test> <!-- testsuite-1 -->
    <test name="testsuite-2" duration-ms="35514" started-at="2017-05-03T12:49:02Z" finished-at="2017-05-03T12:49:37Z">
      <class name="com.chefd.SanityCases">
        <test-method status="PASS" signature="launch_chefd()[pri:0, instance:com.chefd.SanityCases@17d919b6]" name="launch_chefd" is-config="true" duration-ms="4098" started-at="2017-05-03T18:19:02Z" finished-at="2017-05-03T18:19:06Z">
          <reporter-output>
          </reporter-output>
        </test-method> <!-- launch_chefd -->
        <test-method status="FAIL" signature="physical_Gifts_Card()[pri:0, instance:com.chefd.SanityCases@17d919b6]" name="physical_Gifts_Card" duration-ms="31413" started-at="2017-05-03T18:19:06Z" finished-at="2017-05-03T18:19:37Z">
          <exception class="java.lang.AssertionError">
            <message>
              <![CDATA[Adding Physical Gift Card to the cart Failed expected [true] but found [false]]]>
            </message>
            <full-stacktrace>
              <![CDATA[java.lang.AssertionError: Adding Physical Gift Card to the cart Failed expected [true] but found [false]
	at org.testng.Assert.fail(Assert.java:94)
	at org.testng.Assert.failNotEquals(Assert.java:496)
	at org.testng.Assert.assertTrue(Assert.java:42)
	at com.chefd.SanityCases.physical_Gifts_Card(SanityCases.java:33)
	at sun.reflect.NativeMethodAccessorImpl.invoke0(Native Method)
	at sun.reflect.NativeMethodAccessorImpl.invoke(NativeMethodAccessorImpl.java:62)
	at sun.reflect.DelegatingMethodAccessorImpl.invoke(DelegatingMethodAccessorImpl.java:43)
	at java.lang.reflect.Method.invoke(Method.java:498)
	at org.testng.internal.MethodInvocationHelper.invokeMethod(MethodInvocationHelper.java:85)
	at org.testng.internal.Invoker.invokeMethod(Invoker.java:639)
	at org.testng.internal.Invoker.invokeTestMethod(Invoker.java:816)
	at org.testng.internal.Invoker.invokeTestMethods(Invoker.java:1124)
	at org.testng.internal.TestMethodWorker.invokeTestMethods(TestMethodWorker.java:125)
	at org.testng.internal.TestMethodWorker.run(TestMethodWorker.java:108)
	at org.testng.TestRunner.privateRun(TestRunner.java:774)
	at org.testng.TestRunner.run(TestRunner.java:624)
	at org.testng.SuiteRunner.runTest(SuiteRunner.java:359)
	at org.testng.SuiteRunner.runSequentially(SuiteRunner.java:354)
	at org.testng.SuiteRunner.privateRun(SuiteRunner.java:312)
	at org.testng.SuiteRunner.run(SuiteRunner.java:261)
	at org.testng.SuiteRunnerWorker.runSuite(SuiteRunnerWorker.java:52)
	at org.testng.SuiteRunnerWorker.run(SuiteRunnerWorker.java:86)
	at org.testng.TestNG.runSuitesSequentially(TestNG.java:1215)
	at org.testng.TestNG.runSuitesLocally(TestNG.java:1140)
	at org.testng.TestNG.run(TestNG.java:1048)
	at org.testng.remote.AbstractRemoteTestNG.run(AbstractRemoteTestNG.java:132)
	at org.testng.remote.RemoteTestNG.initAndRun(RemoteTestNG.java:230)
	at org.testng.remote.RemoteTestNG.main(RemoteTestNG.java:76)
]]>
            </full-stacktrace>
          </exception> <!-- java.lang.AssertionError -->
          <reporter-output>
          </reporter-output>
        </test-method> <!-- physical_Gifts_Card -->
      </class> <!-- com.chefd.SanityCases -->
    </test> <!-- testsuite-2 -->
  </suite> <!-- MainSuite -->
</testng-results>
